<?xml version="1.0"?>
<robot name="my_robot">

  <material name="blue">
    <color rgba="0 0 0.5 1"/>
  </material>
  
  
  <!-- first link needs to named verbatim base_link -->
  <link name="base_link">
    <visual>
      <geometry>
        <box size="0.3 0.2 0.1" />
      </geometry>
      <origin xyz="0 0 0.05" rpy="0 0 0" />
      <material name="blue"/>
    </visual>
  </link>

  <link name="front_left_wheel_link">
    <visual>
      <geometry>
        <cylinder radius="0.05" length="0.02"/>
      </geometry>
      <origin xyz="0 0.02 0" rpy="1.57 0 0"/>
    </visual>
  </link> 

  <link name="front_right_wheel_link">
    <visual>
      <geometry>
        <cylinder radius="0.05" length="0.02"/>
      </geometry>
      <origin xyz="0 0 0" rpy="1.57 0 0"/>
    </visual>
  </link> 
  
    <link name="back_right_wheel_link">
    <visual>
      <geometry>
        <cylinder radius="0.05" length="0.02"/>
      </geometry>
      <origin xyz="0 0 0" rpy="1.57 0 0"/>
    </visual>
  </link> 
 
  <link name="back_left_wheel_link">
    <visual>
      <geometry>
        <cylinder radius="0.05" length="0.02"/>
      </geometry>
      <origin xyz="0 0.02 0" rpy="1.57 0 0"/>
    </visual>
  </link> 

  <joint name="joint_front_left_shoulder" type="continuous">
    <parent link="base_link"/>
    <child link="front_left_wheel_link"/>
    <origin xyz="0.1 0.1 0" rpy="0 0 0"/>
    <axis xyz="0 1 0"/>
    <!--limit effort="1000.0" velocity="1.0" lower="-3.14" upper="3.14"/-->
  </joint>


  <joint name="joint_front_right_shoulder" type="continuous">
    <parent link="base_link"/>
    <child link="front_right_wheel_link"/>
    <origin xyz="0.1 -0.115 0" rpy="0 0 0"/>
    <axis xyz="0 1 0"/>
    <!--limit effort="1000.0" velocity="1.0" lower="-3.14" upper="3.14"/-->
  </joint>
  
  <joint name="joint_back_right_shoulder" type="continuous">
    <parent link="base_link"/>
    <child link="back_right_wheel_link"/>
    <origin xyz="-0.1 -0.115 0" rpy="0 0 0"/>
    <axis xyz="0 1 0"/>
    <!--limit effort="1000.0" velocity="1.0" lower="-3.14" upper="3.14"/-->
  </joint>
  
  <joint name="joint_back_left_shoulder" type="continuous">
    <parent link="base_link"/>
    <child link="back_left_wheel_link"/>
    <origin xyz="-0.1 0.1 0" rpy="0 0 0"/>
    <axis xyz="0 1 0"/>
    <!--limit effort="1000.0" velocity="1.0" lower="-3.14" upper="3.14"/-->
  </joint>
 
</robot>

