<?xml version="1.0" ?>
<!-- =================================================================================== -->
<!-- |    This document was autogenerated by xacro from /home/niloclol/riot_ws/src/Riot_V3/urdf/riot.urdf.xacro | -->
<!-- |    EDITING THIS FILE BY HAND IS NOT RECOMMENDED                                 | -->
<!-- =================================================================================== -->
<!-- This URDF was automatically created by SolidWorks to URDF Exporter! Originally created by Stephen Brawner (brawner@gmail.com) 
     Commit Version: 1.6.0-4-g7f85cfe  Build Version: 1.6.7995.38578
     For more information, please see http://wiki.ros.org/sw_urdf_exporter -->
<robot name="Riot_V3">
  <!--skid_steer_drive_controller-->
  <gazebo>
    <plugin filename="libgazebo_ros_diff_drive.so" name="riotbot_diff_drive_controller">
      <ros>
        <!--<namespace>/riot</namespace>-->
        <argument>/odom:=odom</argument>
      </ros>
      <update_rate>100.0</update_rate>
      <num_wheel_pairs>2</num_wheel_pairs>
      <odometry_frame>odom</odometry_frame>
      <left_joint>front_left_Joint</left_joint>
      <left_joint>back_left_Joint</left_joint>
      <wheel_separation>0.4</wheel_separation>
      <wheel_diameter>0.2</wheel_diameter>
      <right_joint>front_right_Joint</right_joint>
      <right_joint>back_right_Joint</right_joint>
      <wheel_separation>0.4</wheel_separation>
      <wheel_diameter>0.2</wheel_diameter>
      <robot_base_frame>base_footprint</robot_base_frame>
      <max_wheel_torque>20</max_wheel_torque>
      <publish_odom>true</publish_odom>
      <publish_odom_tf>true</publish_odom_tf>
      <publish_wheel_tf>true</publish_wheel_tf>
      <odometry_source>1</odometry_source>
    </plugin>
  </gazebo>
  <!-- imu sensor 
 <gazebo reference="imu_link">
  <sensor name="imu_sensor" type="imu">
   <plugin filename="libgazebo_ros_imu_sensor.so" name="imu_plugin">
      <ros>
        <namespace>/riot</namespace>
        <remapping>~/out:=imu</remapping>
      </ros>
      <initial_orientation_as_reference>false</initial_orientation_as_reference>
    </plugin>
    <always_on>true</always_on>
    <update_rate>100</update_rate>
    <visualize>true</visualize>
    <imu>
      <angular_velocity>
        <x>
          <noise type="gaussian">
            <mean>0.0</mean>
            <stddev>2e-4</stddev>
            <bias_mean>0.0000075</bias_mean>
            <bias_stddev>0.0000008</bias_stddev>
          </noise>
        </x>
        <y>
          <noise type="gaussian">
            <mean>0.0</mean>
            <stddev>2e-4</stddev>
            <bias_mean>0.0000075</bias_mean>
            <bias_stddev>0.0000008</bias_stddev>
          </noise>
        </y>
        <z>
          <noise type="gaussian">
            <mean>0.0</mean>
            <stddev>2e-4</stddev>
            <bias_mean>0.0000075</bias_mean>
            <bias_stddev>0.0000008</bias_stddev>
          </noise>
        </z>
      </angular_velocity>
      <linear_acceleration>
        <x>
          <noise type="gaussian">
            <mean>0.0</mean>
            <stddev>1.7e-2</stddev>
            <bias_mean>0.1</bias_mean>
            <bias_stddev>0.001</bias_stddev>
          </noise>
        </x>
        <y>
          <noise type="gaussian">
            <mean>0.0</mean>
            <stddev>1.7e-2</stddev>
            <bias_mean>0.1</bias_mean>
            <bias_stddev>0.001</bias_stddev>
          </noise>
        </y>
        <z>
          <noise type="gaussian">
            <mean>0.0</mean>
            <stddev>1.7e-2</stddev>
            <bias_mean>0.1</bias_mean>
            <bias_stddev>0.001</bias_stddev>
          </noise>
        </z>
      </linear_acceleration>
    </imu>
  </sensor>
</gazebo>
-->
  <!-- camera -->
  <gazebo reference="camera">
    <sensor name="camera_sensor" type="camera">
      <update_rate>30.0</update_rate>
      <always_on>1</always_on>
      <camera name="camera">
        <horizontal_fov>1.3962634</horizontal_fov>
        <image>
          <width>800</width>
          <height>800</height>
          <format>R8G8B8</format>
        </image>
        <clip>
          <near>0.02</near>
          <far>300</far>
        </clip>
        <distortion>
          <k1>0.0</k1>
          <k2>0.0</k2>
          <k3>0.0</k3>
          <p1>0.0</p1>
          <p2>0.0</p2>
          <center>0.5 0.5</center>
        </distortion>
      </camera>
      <plugin filename="libgazebo_ros_camera.so" name="riotbot_camera_controller">
        <ros>
          <!--<namespace>/riot</namespace>-->
          <argument>camera/image_raw:=/riot/camera/image</argument>
          <argument>camera/camera_info:=/riot/camera/image/camera_info</argument>
        </ros>
        <camera_name>camera</camera_name>
        <frame_name>camera</frame_name>
        <hack_baseline>0.07</hack_baseline>
      </plugin>
    </sensor>
  </gazebo>
  <!-- hokuyo -->
  <gazebo reference="hokuyo">
    <sensor name="head_hokuyo_sensor" type="ray">
      <pose>0 0 0 0 0 0</pose>
      <visualize>true</visualize>
      <update_rate>40</update_rate>
      <ray>
        <scan>
          <horizontal>
            <samples>720</samples>
            <resolution>1</resolution>
            <min_angle>-1.570796</min_angle>
            <max_angle>1.570796</max_angle>
          </horizontal>
        </scan>
        <range>
          <min>0.10</min>
          <max>30.0</max>
          <resolution>0.01</resolution>
        </range>
        <noise>
          <type>gaussian</type>
          <!-- Noise parameters based on published spec for Hokuyo laser
                achieving "+-30mm" accuracy at range < 10m.  A mean of 0.0m and
                stddev of 0.01m will put 99.7% of samples within 0.03m of the true
                reading. -->
          <mean>0.0</mean>
          <stddev>0.01</stddev>
        </noise>
      </ray>
      <update_rate>30</update_rate>
      <plugin filename="libgazebo_ros_ray_sensor.so" name="riotbot_laserscan">
        <ros>
          <!--<namespace>/riot</namespace>-->
          <argument>~/out:=scan</argument>
        </ros>
        <output_type>sensor_msgs/LaserScan</output_type>
      </plugin>
    </sensor>
  </gazebo>
  <!-- base footprint -->
  <link name="base_footprint"/>
  <!--
  <link name="imu_link">
    <visual>
      <geometry>
        <box size="0.1 0.1 0.1"/>
      </geometry>
    </visual>

    <collision>
      <geometry>
        <box size="0.1 0.1 0.1"/>
      </geometry>
    </collision>
  </link>

  <joint name="imu_joint" type="fixed">
    <parent link="base_link"/>
    <child link="imu_link"/>
    <origin xyz="0 0 0.01"/>
  </joint>
  -->
  <!--base_link-->
  <link name="base_link">
    <inertial>
      <origin rpy="0 0 0" xyz="-0.00731924788401569 -0.000495519981526249 0.148055312329441"/>
      <mass value="23.8011559593027"/>
      <inertia ixx="0.263039373455415" ixy="-9.77830112583802E-09" ixz="0.00557641591684923" iyy="0.404190875888997" iyz="-5.8000914660657E-05" izz="0.446699879113429"/>
    </inertial>
    <visual>
      <origin rpy="0 0 0" xyz="0 0 0"/>
      <geometry>
        <mesh filename="file:///home/niloclol/riot_ws/install/Riot_V3/share/Riot_V3/meshes/base_link.STL"/>
      </geometry>
      <material name="">
        <color rgba="0.298039215686275 0.298039215686275 0.298039215686275 1"/>
      </material>
    </visual>
    <collision>
      <origin rpy="0 0 0" xyz="0 0 0"/>
      <geometry>
        <mesh filename="file:///home/niloclol/riot_ws/install/Riot_V3/share/Riot_V3/meshes/base_link.STL"/>
      </geometry>
    </collision>
  </link>
  <joint name="base_joint" type="fixed">
    <parent link="base_footprint"/>
    <child link="base_link"/>
    <origin rpy="0 0 0" xyz="0.0 0.0 0.1"/>
  </joint>
  <link name="front_left_Link">
    <inertial>
      <origin rpy="0 0 0" xyz="-2.91433543964104E-16 0.0727451186755974 5.55111512312578E-17"/>
      <mass value="0.238445952331711"/>
      <inertia ixx="0.000175182461271135" ixy="7.66564817265142E-20" ixz="-1.7205356741103E-21" iyy="0.000265785034598442" iyz="4.06575814682064E-20" izz="0.000175182461271135"/>
    </inertial>
    <visual>
      <origin rpy="0 0 0" xyz="0 0 0"/>
      <geometry>
        <mesh filename="file:///home/niloclol/riot_ws/install/Riot_V3/share/Riot_V3/meshes/front_left_Link.STL"/>
      </geometry>
      <material name="">
        <color rgba="0.298039215686275 0.298039215686275 0.298039215686275 1"/>
      </material>
    </visual>
    <collision>
      <origin rpy="0 0 0" xyz="0 0 0"/>
      <geometry>
        <mesh filename="file:///home/niloclol/riot_ws/install/Riot_V3/share/Riot_V3/meshes/front_left_Link.STL"/>
      </geometry>
    </collision>
  </link>
  <joint name="front_left_Joint" type="continuous">
    <origin rpy="0 0 0" xyz="0.095 0.059124 0.05"/>
    <parent link="base_link"/>
    <child link="front_left_Link"/>
    <axis xyz="0 -1 0"/>
  </joint>
  <link name="front_right_Link">
    <inertial>
      <origin rpy="0 0 0" xyz="-5.82867087928207E-16 0.0301635935595795 -1.66533453693773E-16"/>
      <mass value="0.238445952331711"/>
      <inertia ixx="0.000175182461271135" ixy="6.73391193067169E-20" ixz="1.46642578993401E-20" iyy="0.000265785034598442" iyz="2.96461531539005E-20" izz="0.000175182461271135"/>
    </inertial>
    <visual>
      <origin rpy="0 0 0" xyz="0 0 0"/>
      <geometry>
        <mesh filename="file:///home/niloclol/riot_ws/install/Riot_V3/share/Riot_V3/meshes/front_right_Link.STL"/>
      </geometry>
      <material name="">
        <color rgba="0.298039215686275 0.298039215686275 0.298039215686275 1"/>
      </material>
    </visual>
    <collision>
      <origin rpy="0 0 0" xyz="0 0 0"/>
      <geometry>
        <mesh filename="file:///home/niloclol/riot_ws/install/Riot_V3/share/Riot_V3/meshes/front_right_Link.STL"/>
      </geometry>
    </collision>
  </link>
  <joint name="front_right_Joint" type="continuous">
    <origin rpy="0 0 0" xyz="0.095 -0.16302 0.05"/>
    <parent link="base_link"/>
    <child link="front_right_Link"/>
    <axis xyz="0 1 0"/>
  </joint>
  <link name="back_left_Link">
    <inertial>
      <origin rpy="0 0 0" xyz="-7.21644966006352E-16 0.0740350172559949 2.77555756156289E-16"/>
      <mass value="0.238445952331711"/>
      <inertia ixx="0.000175182461271135" ixy="6.09863722023096E-20" ixz="-2.75021010061631E-20" iyy="0.000265785034598442" iyz="4.2351647362715E-20" izz="0.000175182461271135"/>
    </inertial>
    <visual>
      <origin rpy="0 0 0" xyz="0 0 0"/>
      <geometry>
        <mesh filename="file:///home/niloclol/riot_ws/install/Riot_V3/share/Riot_V3/meshes/back_left_Link.STL"/>
      </geometry>
      <material name="">
        <color rgba="0.298039215686275 0.298039215686275 0.298039215686275 1"/>
      </material>
    </visual>
    <collision>
      <origin rpy="0 0 0" xyz="0 0 0"/>
      <geometry>
        <mesh filename="file:///home/niloclol/riot_ws/install/Riot_V3/share/Riot_V3/meshes/back_left_Link.STL"/>
      </geometry>
    </collision>
  </link>
  <joint name="back_left_Joint" type="continuous">
    <origin rpy="0 0 0" xyz="-0.095 0.057834 0.05"/>
    <parent link="base_link"/>
    <child link="back_left_Link"/>
    <axis xyz="0 -1 0"/>
  </joint>
  <link name="back_right_Link">
    <inertial>
      <origin rpy="0 0 0" xyz="0 0.0293283726076817 1.11022302462516E-16"/>
      <mass value="0.238445952331711"/>
      <inertia ixx="0.000175182461271135" ixy="6.39509875176997E-20" ixz="-2.8640301529036E-20" iyy="0.000265785034598442" iyz="3.55753837846806E-20" izz="0.000175182461271135"/>
    </inertial>
    <visual>
      <origin rpy="0 0 0" xyz="0 0 0"/>
      <geometry>
        <mesh filename="file:///home/niloclol/riot_ws/install/Riot_V3/share/Riot_V3/meshes/back_right_Link.STL"/>
      </geometry>
      <material name="">
        <color rgba="0.298039215686275 0.298039215686275 0.298039215686275 1"/>
      </material>
    </visual>
    <collision>
      <origin rpy="0 0 0" xyz="0 0 0"/>
      <geometry>
        <mesh filename="file:///home/niloclol/riot_ws/install/Riot_V3/share/Riot_V3/meshes/back_right_Link.STL"/>
      </geometry>
    </collision>
  </link>
  <joint name="back_right_Joint" type="continuous">
    <origin rpy="0 0 0" xyz="-0.095 -0.16219 0.05"/>
    <parent link="base_link"/>
    <child link="back_right_Link"/>
    <axis xyz="0 1 0"/>
  </joint>
  <link name="camera">
    <inertial>
      <origin rpy="0 0 0" xyz="0.00836854131407994 0 -5.55111512312578E-17"/>
      <mass value="0.00523598775598299"/>
      <inertia ixx="2.40855436775218E-07" ixy="4.96308367531817E-24" ixz="1.65436122510606E-24" iyy="2.55254403104171E-07" iyz="1.65436122510606E-24" izz="2.55254403104171E-07"/>
    </inertial>
    <visual>
      <origin rpy="0 0 0" xyz="0 0 0"/>
      <geometry>
        <mesh filename="file:///home/niloclol/riot_ws/install/Riot_V3/share/Riot_V3/meshes/camera.STL"/>
      </geometry>
      <material name="">
        <color rgba="0.792156862745098 0.819607843137255 0.933333333333333 1"/>
      </material>
    </visual>
    <collision>
      <origin rpy="0 0 0" xyz="0 0 0"/>
      <geometry>
        <mesh filename="file:///home/niloclol/riot_ws/install/Riot_V3/share/Riot_V3/meshes/camera.STL"/>
      </geometry>
    </collision>
  </link>
  <joint name="camera_Joint" type="fixed">
    <origin rpy="0 0 0" xyz="0.19013 -0.00049552 0.22089"/>
    <parent link="base_link"/>
    <child link="camera"/>
    <axis xyz="1 0 0"/>
  </joint>
  <link name="hokuyo">
    <inertial>
      <origin rpy="0 0 0" xyz="1.38777878078145E-17 5.55111512312578E-17 0.0193003055082826"/>
      <mass value="0.171029210078734"/>
      <inertia ixx="8.16653772390185E-05" ixy="4.2351647362715E-22" ixz="1.4849546356552E-20" iyy="8.16653772390186E-05" iyz="2.5410988417629E-21" izz="0.00011937610828968"/>
    </inertial>
    <visual>
      <origin rpy="0 0 0" xyz="0 0 0"/>
      <geometry>
        <mesh filename="file:///home/niloclol/riot_ws/install/Riot_V3/share/Riot_V3/meshes/hokuyo.STL"/>
      </geometry>
      <material name="">
        <color rgba="0.792156862745098 0.819607843137255 0.933333333333333 1"/>
      </material>
    </visual>
    <collision>
      <origin rpy="0 0 0" xyz="0 0 0"/>
      <geometry>
        <mesh filename="file:///home/niloclol/riot_ws/install/Riot_V3/share/Riot_V3/meshes/hokuyo.STL"/>
      </geometry>
    </collision>
  </link>
  <joint name="hokuyo_Joint" type="fixed">
    <origin rpy="0 0 0" xyz="0.14 -0.00049552 0.14987"/>
    <parent link="base_link"/>
    <child link="hokuyo"/>
    <axis xyz="0 0 1"/>
  </joint>
</robot>
